Workbook
Name UPDATE: #REF!

Sheet Profit & Loss
B1: GRIVA PRIVATE LTD.
F2: (Figures are in ₹ Crores)
B3: Particulars | C3: Notes | D3: 2018-19 | E3: 2019-20 | F3: 2020-21 | G3: 2021-22 | H3: 2022-23 | I3: 2023-24
B5: Sales | C5: 1 | D5: 39310 | E5: 39783 | F5: 47028 | G5: =Workings!G8 -> 51751.492 | H5: =Workings!H8 -> 57416.625 | I5: =Workings!I8 -> 63846.23
B6: Expenses
B7: Raw Material Cost | C7: 4 | D7: 15845 | E7: 15697 | F7: 20141 | G7: =Workings!G24 -> 24130.716 | H7: =Workings!H24 -> 26772.257 | I7: =Workings!I24 -> 29770.257
B8: Power and Fuel | C8: 6 | D8: 308 | E8: 299 | F8: 339 | G8: =Workings!G36 -> 352.56 | H8: =Workings!H36 -> 367.22175 | I8: =Workings!I36 -> 408.5011
B9: Other Manufacuring cost | D9: 3041 | E9: 2906 | F9: 2868 | G9: =F9-F9*2/100 -> 2810.64 | H9: =G9-G9*0.5/100 -> 2796.5868 | I9: =H9-H9*0.5/100 -> 2782.6039
B10: Employee Cost | D10: 1875 | E10: 1820 | F10: 2358 | G10: =F10+F10*1.5/100 -> 2393.37 | H10: =G10+G10*1.5/100 -> 2429.2705 | I10: =H10+H10*1.5/100 -> 2465.7096
B11: Other Expenses | D11: 1553 | E11: 1696 | F11: 2196 | G11: =F11-F11*2.5/100 -> 2141.1 | H11: =G11-G11*2.5/100 -> 2087.5725 | I11: =H11-H11*2.5/100 -> 2035.3832
B12: Selling and adminitration cost | D12: 7796 | E12: 7620 | F12: 7906 | G12: =F12-3378.71 -> 4527.29 | H12: =G12 -> 4527.29 | I12: =G12 -> 4527.29
A13: Cl.-Op. | B13: Change in Inventory | D13: -12 | E13: ='Balance Sheet'!E18-'Balance Sheet'!D18 -> 193 | F13: ='Balance Sheet'!F18-'Balance Sheet'!E18 -> 812 | G13: ='Balance Sheet'!G18-'Balance Sheet'!F18 -> -885.09184 | H13: ='Balance Sheet'!H18-'Balance Sheet'!G18 -> 1571.7746 | I13: ='Balance Sheet'!I18-'Balance Sheet'!H18 -> -792.42843
B14: Total Expenses | D14: =SUM(D7:D12,-1*D13) -> 30430 | E14: =SUM(E7:E12,-1*E13) -> 29845 | F14: =SUM(F7:F12,-1*F13) -> 34996 | G14: =SUM(G7:G12)-1*G13 -> 37240.767 | H14: =SUM(H7:H12)-1*H13 -> 37408.424 | I14: =SUM(I7:I12)-1*I13 -> 42782.173
B15: Operating Profit | D15: =D5-D14 -> 8880 | E15: =E5-E14 -> 9938 | F15: =F5-F14 -> 12032 | G15: =G5-G14 -> 14510.725 | H15: =H5-H14 -> 20008.201 | I15: =I5-I14 -> 21064.057
B16: Investment Income | D16: 322 | E16: 432 | F16: 171 | G16: =F16 -> 171 | H16: =G16 -> 171 | I16: =H16 -> 171
B17: Depreciation | C17: 7 | D17: 850 | E17: 1002 | F17: 1074 | G17: =Workings!G49 -> 1122.7317 | H17: =Workings!H49 -> 1156.9214 | I17: =Workings!I49 -> 1178.6057
B18: Interest | C18: 8 | D18: 54 | E18: 139 | F18: 138 | G18: =F18-F18*15/100+Workings!G61 -> 156.4104 | H18: =117.3+Workings!H61 -> 182.35321 | I18: =117.3+Workings!I61 -> 199.38145
B19: Profit before tax | D19: =D15+D16-D17-D18 -> 8298 | E19: =E15+E16-E17-E18 -> 9229 | F19: =F15+F16-F17-F18 -> 10991 | G19: =G15+G16-G17-G18 -> 13402.583 | H19: =H15+H16-H17-H18 -> 18839.926 | I19: =I15+I16-I17-I18 -> 19857.07
B20: Tax | D20: 2544 | E20: 2409 | F20: 2606 | G20: =G19*30/100 -> 4020.7748 | H20: =H19*30/100 -> 5651.9779 | I20: =I19*30/100 -> 5957.1209
B21: Net profit | D21: =D19-D20 -> 5754 | E21: =E19-E20 -> 6820 | F21: =F19-F20 -> 8385 | G21: =G19-G20 -> 9381.8079 | H21: =H19-H20 -> 13187.948 | I21: =I19-I20 -> 13899.949
B23: OPM | D23: =D15/D5 -> 0.22589672 | E23: =E15/E5 -> 0.24980519 | F23: =F15/F5 -> 0.25584758 | G23: =G15/G5 -> 0.28039239 | H23: =H15/H5 -> 0.348474 | I23: =I15/I5 -> 0.32991857

Sheet Balance Sheet
B1: ='Profit & Loss'!B1 -> GRIVA PRIVATE LTD.
F2: (Figures are in ₹ Crores)
B3: Particulars | C3: Notes | D3: 2018-19 | E3: 2019-20 | F3: 2020-21 | G3: 2021-22 | H3: 2022-23 | I3: 2023-24
B5: Equity Share Capital | D5: 216 | E5: 216 | F5: 235 | G5: 235 | H5: 235 | I5: 235
B6: Reserves | D6: 14914 | E6: 17208 | F6: 28865 | G6: =F6+'Profit & Loss'!G21 -> 38246.808 | H6: ='Profit & Loss'!H21+G6 -> 51434.756 | I6: =H6+'Profit & Loss'!I21 -> 65334.705
B7: Borrowings | C7: 8 | D7: 99 | E7: 0 | F7: 0 | G7: =Workings!G62 -> 434.56 | H7: =Workings!H62 -> 722.8134 | I7: =Workings!I62 -> 912.01615
B8: Other Liabilities
B9: Trade Payables | C9: 4 | D9: 7160 | E9: 7415 | F9: 8700 | G9: =Workings!G30 -> 6548.4775 | H9: =Workings!H30 -> 10369.22 | I9: =Workings!I30 -> 8442.9484
B10: Other liability items | D10: 3442 | E10: 4334 | F10: 12250 | G10: =F10-F10*15/100 -> 10412.5 | H10: =G10 -> 10412.5 | I10: =G10 -> 10412.5
B11: Total Liabilities | D11: =SUM(D9:D10) -> 10602 | E11: =SUM(E9:E10) -> 11749 | F11: =SUM(F9:F10) -> 20950 | G11: =SUM(G9:G10) -> 16960.978 | H11: =SUM(H9:H10) -> 20781.72 | I11: =SUM(I9:I10) -> 18855.448
B12: Total Equity and Liabilities | D12: =SUM(D5:D7,D11) -> 25831 | E12: =SUM(E5:E7,E11) -> 29173 | F12: =SUM(F5:F7,F11) -> 50050 | G12: =SUM(G5:G7,G11) -> 55877.345 | H12: =SUM(H5:H7,H11) -> 73174.29 | I12: =ROUND(SUM(I5:I7,I11),0) -> 85337
B14: Net Block of Fixed Asset | C14: 7 | D14: 5200 | E14: 5479 | F14: 10119 | G14: =Workings!G50 -> 10008.168 | H14: =Workings!H50 -> 9852.0638 | I14: =Workings!I50 -> 9658.5532
B15: Capital Work in Progress | C15: 8 | D15: 450 | E15: 597 | F15: 745 | G15: =F15+F15*10/100 -> 819.5 | H15: =G15+G15*10/100 -> 901.45 | I15: =H15+H15*10/100 -> 991.595
B16: Investments | D16: 1716 | E16: 1255 | F16: 2709 | G16: 2709 | H16: 2709 | I16: 2709
B17: Other Assets
B18: Inventories | C18: 2 | D18: 2574 | E18: 2767 | F18: 3579 | G18: =Workings!G13 -> 2693.9082 | H18: =Workings!H13 -> 4265.6827 | I18: =Workings!I13 -> 3473.2543
B19: Trade receivables | C19: 3 | D19: =1816-43 -> 1773 | E19: =1149-158 -> 991 | F19: =1758-96 -> 1662 | G19: =Workings!G18 -> 925.57462 | H19: =Workings!H18 -> 1945.2566 | I19: =Workings!I18 -> 1247.0549
B20: Cash Equivalents | C20: Cash Flow | D20: 9473 | E20: 14291 | F20: 27201 | G20: ='Cash Flow'!E39 -> 34686.194 | H20: ='Cash Flow'!F39 -> 49465.837 | I20: ='Cash Flow'!G39 -> 63222.601
B21: Loans and Advances | D21: 1878 | E21: 2323 | F21: 1719 | G21: 1719 | H21: 1719 | I21: 1719
B22: Deposits | D22: 2767 | E22: 1470 | F22: 2316 | G22: 2316 | H22: 2316 | I22: 2316
B23: Total Other Assets | D23: =SUM(D18:D22) -> 18465 | E23: =SUM(E18:E22) -> 21842 | F23: =SUM(F18:F22) -> 36477 | G23: =SUM(G18:G22) -> 42340.677 | H23: =SUM(H18:H22) -> 59711.776 | I23: =SUM(I18:I22) -> 71977.91
B24: Total Assets | D24: =SUM(D14:D16,D23) -> 25831 | E24: =SUM(E14:E16,E23) -> 29173 | F24: =SUM(F14:F16,F23) -> 50050 | G24: =SUM(G14:G16)+G23 -> 55877.345 | H24: =SUM(H14:H16)+H23 -> 73174.29 | I24: =ROUND(SUM(I14:I16)+I23,0) -> 85337
D26: =D12-D24 -> 0 | E26: =E12-E24 -> 0 | F26: =F12-F24 -> 0 | G26: =G12-G24 -> 0 | H26: =H12-H24 -> 0 | I26: =I12-I24 -> 0

Sheet Cash Flow
B1: ='Profit & Loss'!B1 -> GRIVA PRIVATE LTD.
D2: (Figures are in ₹ Crores)
B3: Particulars | C3: 2019-20 | D3: 2020-21 | E3: 2021-22 | F3: 2022-23 | G3: 2023-24
B5: Cash from Operating Activity
B6: Net profit | C6: ='Profit & Loss'!E21 -> 6820 | D6: ='Profit & Loss'!F21 -> 8385 | E6: ='Profit & Loss'!G21 -> 9381.8079 | F6: ='Profit & Loss'!H21 -> 13187.948 | G6: ='Profit & Loss'!I21 -> 13899.949
B7: Add: Taxes expenses | C7: ='Profit & Loss'!E20 -> 2409 | D7: ='Profit & Loss'!F20 -> 2606 | E7: ='Profit & Loss'!G20 -> 4020.7748 | F7: ='Profit & Loss'!H20 -> 5651.9779 | G7: ='Profit & Loss'!I20 -> 5957.1209
B8: Profit before tax | C8: =C6+C7 -> 9229 | D8: =D6+D7 -> 10991 | E8: =E6+E7 -> 13402.583 | F8: =F6+F7 -> 18839.926 | G8: =G6+G7 -> 19857.07
B9: Less: Investment Income | C9: ='Profit & Loss'!E16 -> 432 | D9: ='Profit & Loss'!F16 -> 171 | E9: ='Profit & Loss'!G16 -> 171 | F9: ='Profit & Loss'!H16 -> 171 | G9: ='Profit & Loss'!I16 -> 171
B10: Add: Depreciation | C10: ='Profit & Loss'!E17 -> 1002 | D10: ='Profit & Loss'!F17 -> 1074 | E10: ='Profit & Loss'!G17 -> 1122.7317 | F10: ='Profit & Loss'!H17 -> 1156.9214 | G10: ='Profit & Loss'!I17 -> 1178.6057
B11: Add: Interest | C11: ='Profit & Loss'!E18 -> 139 | D11: ='Profit & Loss'!F18 -> 138 | E11: ='Profit & Loss'!G18 -> 156.4104 | F11: ='Profit & Loss'!H18 -> 182.35321 | G11: ='Profit & Loss'!I18 -> 199.38145
B12: Operating profit before working capital changes | C12: =C8-C9+SUM(C10:C11) -> 9938 | D12: =D8-D9+SUM(D10:D11) -> 12032 | E12: =E8-E9+SUM(E10:E11) -> 14510.725 | F12: =F8-F9+SUM(F10:F11) -> 20008.201 | G12: =G8-G9+SUM(G10:G11) -> 21064.057
B13: Inventory | C13: ='Balance Sheet'!D18-'Balance Sheet'!E18 -> -193 | D13: ='Balance Sheet'!E18-'Balance Sheet'!F18 -> -812 | E13: ='Balance Sheet'!F18-'Balance Sheet'!G18 -> 885.09184 | F13: ='Balance Sheet'!G18-'Balance Sheet'!H18 -> -1571.7746 | G13: ='Balance Sheet'!H18-'Balance Sheet'!I18 -> 792.42843 | H13: Op.-Cl.
B14: Receivables | C14: ='Balance Sheet'!D19-'Balance Sheet'!E19 -> 782 | D14: ='Balance Sheet'!E19-'Balance Sheet'!F19 -> -671 | E14: ='Balance Sheet'!F19-'Balance Sheet'!G19 -> 736.42538 | F14: ='Balance Sheet'!G19-'Balance Sheet'!H19 -> -1019.682 | G14: ='Balance Sheet'!H19-'Balance Sheet'!I19 -> 698.20173 | H14: Op.-Cl.
B15: Loans Advances | C15: ='Balance Sheet'!D21-'Balance Sheet'!E21 -> -445 | D15: ='Balance Sheet'!E21-'Balance Sheet'!F21 -> 604 | E15: ='Balance Sheet'!F21-'Balance Sheet'!G21 -> 0 | F15: ='Balance Sheet'!G21-'Balance Sheet'!H21 -> 0 | G15: ='Balance Sheet'!H21-'Balance Sheet'!I21 -> 0 | H15: Op.-Cl.
B16: Deposits | C16: ='Balance Sheet'!D22-'Balance Sheet'!E22 -> 1297 | D16: ='Balance Sheet'!E22-'Balance Sheet'!F22 -> -846 | E16: ='Balance Sheet'!F22-'Balance Sheet'!G22 -> 0 | F16: ='Balance Sheet'!G22-'Balance Sheet'!H22 -> 0 | G16: ='Balance Sheet'!H22-'Balance Sheet'!I22 -> 0 | H16: Op.-Cl.
B17: Payables | C17: ='Balance Sheet'!E9-'Balance Sheet'!D9 -> 255 | D17: ='Balance Sheet'!F9-'Balance Sheet'!E9 -> 1285 | E17: ='Balance Sheet'!G9-'Balance Sheet'!F9 -> -2151.5225 | F17: ='Balance Sheet'!H9-'Balance Sheet'!G9 -> 3820.7428 | G17: ='Balance Sheet'!I9-'Balance Sheet'!H9 -> -1926.272 | H17: Cl.-Op.
B18: Other liability items | C18: ='Balance Sheet'!E10-'Balance Sheet'!D10 -> 892 | D18: ='Balance Sheet'!F10-'Balance Sheet'!E10 -> 7916 | E18: ='Balance Sheet'!G10-'Balance Sheet'!F10 -> -1837.5 | F18: ='Balance Sheet'!H10-'Balance Sheet'!G10 -> 0 | G18: ='Balance Sheet'!I10-'Balance Sheet'!H10 -> 0 | H18: Cl.-Op.
B19: Operating profit before tax | C19: =C12+SUM(C13:C18) -> 12526 | D19: =D12+SUM(D13:D18) -> 19508 | E19: =E12+SUM(E13:E18) -> 12143.22 | F19: =F12+SUM(F13:F18) -> 21237.487 | G19: =G12+SUM(G13:G18) -> 20628.415
B20: Less: Tax paid | C20: =C7 -> 2409 | D20: =D7 -> 2606 | E20: =E7 -> 4020.7748 | F20: =F7 -> 5651.9779 | G20: =G7 -> 5957.1209
C21: =C19-C20 -> 10117 | D21: =D19-D20 -> 16902 | E21: =E19-E20 -> 8122.4447 | F21: =F19-F20 -> 15585.509 | G21: =G19-G20 -> 14671.294
B23: Cash Flow from Investing Activity
B24: Fixed Assets purchased | C24: ='Balance Sheet'!D14-'Balance Sheet'!E14 -> -279 | D24: ='Balance Sheet'!E14-'Balance Sheet'!F14 -> -4640 | E24: =-(Workings!G45) -> -1011.9 | F24: =-(Workings!H45) -> -1000.8168 | G24: =-(Workings!I45) -> -985.20638
B25: Capital Work in Progress | C25: ='Balance Sheet'!D15-'Balance Sheet'!E15 -> -147 | D25: ='Balance Sheet'!E15-'Balance Sheet'!F15 -> -148 | E25: =-(Workings!G53) -> -74.5 | F25: =-(Workings!H53) -> -81.95 | G25: =-(Workings!I53) -> -90.145
B26: Investments purchased | C26: 0 | D26: ='Balance Sheet'!E16-'Balance Sheet'!F16 -> -1454 | E26: ='Balance Sheet'!F16-'Balance Sheet'!G16 -> 0 | F26: ='Balance Sheet'!G16-'Balance Sheet'!H16 -> 0 | G26: ='Balance Sheet'!H16-'Balance Sheet'!I16 -> 0
B27: Investments sold | C27: ='Balance Sheet'!D16-'Balance Sheet'!E16 -> 461 | D27: 0 | E27: 0 | F27: 0 | G27: 0
B28: Income on Investment (Interest, Dividend) | C28: ='Profit & Loss'!E16 -> 432 | D28: ='Profit & Loss'!F16 -> 171 | E28: ='Profit & Loss'!G16 -> 171 | F28: ='Profit & Loss'!H16 -> 171 | G28: ='Profit & Loss'!I16 -> 171
C29: =SUM(C24:C28) -> 467 | D29: =SUM(D24:D28) -> -6071 | E29: =SUM(E24:E28) -> -915.4 | F29: =SUM(F24:F28) -> -911.76683 | G29: =SUM(G24:G28) -> -904.35138
B31: Cash Flow from Financing Activity
B32: Borrowings made | E32: =Workings!G56 -> 651.84 | F32: =Workings!H56 -> 649.6601 | G32: =Workings!I56 -> 645.21083
B33: Repayment of borrowings | C33: ='Balance Sheet'!E7-'Balance Sheet'!D7 -> -99 | E33: =-(Workings!G60) -> -217.28 | F33: =-(Workings!H60) -> -361.4067 | G33: =-(Workings!I60) -> -456.00808
B34: Interest paid | C34: =-('Profit & Loss'!E18) -> -139 | D34: =-('Profit & Loss'!F18) -> -138 | E34: =-('Profit & Loss'!G18) -> -156.4104 | F34: =-('Profit & Loss'!H18) -> -182.35321 | G34: =-('Profit & Loss'!I18) -> -199.38145
C35: =SUM(C32:C34) -> -238 | D35: =SUM(D32:D34) -> -138 | E35: =SUM(E32:E34) -> 278.1496 | F35: =SUM(F32:F34) -> 105.90019 | G35: =SUM(G32:G34) -> -10.178701
B37: Net Cash Flow | C37: =C35+C29+C21 -> 10346 | D37: =D35+D29+D21 -> 10693 | E37: =E21+E29+E35 -> 7485.1943 | F37: =F21+F29+F35 -> 14779.643 | G37: =G21+G29+G35 -> 13756.764
B38: Opening Cash | C38: ='Balance Sheet'!D20 -> 9473 | D38: ='Balance Sheet'!E20 -> 14291 | E38: ='Balance Sheet'!F20 -> 27201 | F38: =E39 -> 34686.194 | G38: =F39 -> 49465.837
B39: Closing Cash | C39: =C37+C38 -> 19819 | D39: =D37+D38 -> 24984 | E39: =E37+E38 -> 34686.194 | F39: =F37+F38 -> 49465.837 | G39: =G37+G38 -> 63222.601

Sheet Workings
B2: Name | C2: Formula | D2: 2018-19 | E2: 2019-20 | F2: 2020-21 | G2: 2021-22 | H2: 2022-23 | I2: 2023-24
B3: Note 1
B4: Total Growth Rate of 5 years | G4: =F6+E6+D6+7.19+3.03 -> 40.22 | H4: =G6+F6+E6+D6+7.19 -> 47.234 | I4: =H6+G6+F6+E6+D6 -> 50.9908
B6: Growth rate | D6: 10.59 | E6: 1.2 | F6: 18.21 | G6: =G4/5+6-4 -> 10.044 | H6: =H4/5+6-4.5 -> 10.9468 | I6: =I4/5+6-5 -> 11.19816
B8: Sales | D8: ='Profit & Loss'!D5 -> 39310 | E8: ='Profit & Loss'!E5 -> 39783 | F8: ='Profit & Loss'!F5 -> 47028 | G8: =F8+F8*G6/100 -> 51751.492 | H8: =G8+G8*H6/100 -> 57416.625 | I8: =H8+H8*I6/100 -> 63846.23
B10: Note 2
B11: Inventory Turnover Ratio | C11: Sales/Average Inventory | E11: ='Profit & Loss'!E5/E12 -> 14.89721 | F11: ='Profit & Loss'!F5/F12 -> 14.821305 | G11: 16.5 | H11: 16.5 | I11: 16.5
C12: Average Inventory | E12: =('Balance Sheet'!D18+'Balance Sheet'!E18)/2 -> 2670.5 | F12: =(E13+F13)/2 -> 3173 | G12: =G8/G11 -> 3136.4541 | H12: =H8/H11 -> 3479.7954 | I12: =I8/I11 -> 3869.4685
C13: Closing Inventory | E13: ='Balance Sheet'!E18 -> 2767 | F13: ='Balance Sheet'!F18 -> 3579 | G13: =G12*2-F13 -> 2693.9082 | H13: =H12*2-G13 -> 4265.6827 | I13: =I12*2-H13 -> 3473.2543
B15: Note 3
B16: Receivables Turnover Ratio | C16: Sales/Average Receivables | F16: ='Profit & Loss'!F5/F17 -> 35.452695 | G16: 40 | H16: 40 | I16: 40
C17: Average receivables | F17: =('Balance Sheet'!E19+'Balance Sheet'!F19)/2 -> 1326.5 | G17: ='Profit & Loss'!G5/G16 -> 1293.7873 | H17: ='Profit & Loss'!H5/H16 -> 1435.4156 | I17: ='Profit & Loss'!I5/I16 -> 1596.1558
C18: Closing receivables | E18: ='Balance Sheet'!E19 -> 991 | F18: ='Balance Sheet'!F19 -> 1662 | G18: =G17*2-'Balance Sheet'!F19 -> 925.57462 | H18: =H17*2-'Balance Sheet'!G19 -> 1945.2566 | I18: =I17*2-'Balance Sheet'!H19 -> 1247.0549
B20: Note 4
B21: Payables Turnover Ratio | C21: Purchases/Average Payables | F21: ='Profit & Loss'!F7/F22 -> 2.4996587 | G21: 3 | H21: 3 | I21: 3
C22: Average Payables | F22: =(E25+F25)/2 -> 8057.5 | G22: =(F25+G25)/2 -> 7624.2388 | H22: =(G25+H25)/2 -> 8458.8489 | I22: =(H25+I25)/2 -> 9406.0844
C23: Raw material purchases | F23: ='Profit & Loss'!F7 -> 20141 | G23: =G22*G21 -> 22872.716 | H23: =H22*H21 -> 25376.547 | I23: =I22*I21 -> 28218.253
C24: With 5.5% hike | D24: =5.5/100 -> 0.055 | G24: =G23+G23*D24 -> 24130.716 | H24: =H23+H23*D24 -> 26772.257 | I24: =I23+I23*D24 -> 29770.257
C25: Closing Payables | E25: ='Balance Sheet'!E9 -> 7415 | F25: ='Balance Sheet'!F9 -> 8700 | G25: =G30 -> 6548.4775 | H25: =H30 -> 10369.22 | I25: =I30 -> 8442.9484
B26: Payables Turnover Ratio | C26: Purchases/Average Payables | G26: =G24/G22 -> 3.165 | H26: =H24/H22 -> 3.165 | I26: =I24/I22 -> 3.165
B28: Note 5
B29: Payables to Inventory Ratio | C29: Payables/Inventory | F29: =F25/F13 -> 2.4308466 | G29: =F29 -> 2.4308466 | H29: =G29 -> 2.4308466 | I29: =H29 -> 2.4308466
C30: Closing Payables | G30: =G13*G29 -> 6548.4775 | H30: =H13*H29 -> 10369.22 | I30: =I13*I29 -> 8442.9484
B32: Note 6
B33: Petrol-diesel cost | E33: ='Profit & Loss'!E8*1/4 -> 74.75 | F33: ='Profit & Loss'!F8*1/4 -> 84.75 | G33: =F33+F33*7/100 -> 90.6825 | H33: =G33+G33*7/100 -> 97.030275 | I33: =H33+H33*7/100 -> 103.82239
B34: Oil & energy cost | E34: ='Profit & Loss'!E8*1/4 -> 74.75 | F34: ='Profit & Loss'!F8*1/4 -> 84.75 | G34: =F34+F34*9/100 -> 92.3775 | H34: =G34+G34*9/100 -> 100.69147 | I34: =H34+H34*9/100 -> 109.75371
B35: Electricity cost | E35: ='Profit & Loss'!E8*2/4 -> 149.5 | F35: ='Profit & Loss'!F8*2/4 -> 169.5 | G35: =F35 -> 169.5 | H35: =F35 -> 169.5 | I35: =H35+H35*15/100 -> 194.925
B36: Total Power and Fuel cost | E36: =SUM(E33:E35) -> 299 | F36: =SUM(F33:F35) -> 339 | G36: =SUM(G33:G35) -> 352.56 | H36: =SUM(H33:H35) -> 367.22175 | I36: =SUM(I33:I35) -> 408.5011
B38: Note 7
B39: Opening ( Existing Assets ) | D39: =D42+D40 -> 6050 | E39: =E42+E40 -> 6481 | F39: =F42+F40 -> 11193 | G39: =F42 -> 10119 | H39: =G42 -> 9148.0533 | I39: =H42 -> 8270.2718
B40: Depreciation | D40: ='Profit & Loss'!D17 -> 850 | E40: ='Profit & Loss'!E17 -> 1002 | F40: ='Profit & Loss'!F17 -> 1074 | G40: =G39*F41 -> 970.94666 | H40: =H39*H41 -> 877.78159 | I40: =I39*I41 -> 793.55596
B41: Average Rate of Depreciation | F41: =F40/F39 -> 0.095952828 | G41: =F41 -> 0.095952828 | H41: =F41 -> 0.095952828 | I41: =F41 -> 0.095952828
B42: Closing ( Existing Assets ) | D42: ='Balance Sheet'!D14 -> 5200 | E42: ='Balance Sheet'!E14 -> 5479 | F42: ='Balance Sheet'!F14 -> 10119 | G42: =G39-G40 -> 9148.0533 | H42: =H39-H40 -> 8270.2718 | I42: =I39-I40 -> 7476.7158
B44: Opening | G44: 0 | H44: =G47 -> 860.115 | I44: =H47 -> 1581.7921
B45: Additional Capex | G45: =G39*10/100 -> 1011.9 | H45: =G50*10/100 -> 1000.8168 | I45: =H50*10/100 -> 985.20638
B46: Additional Depreciation @ 15% | G46: =G45*15/100 -> 151.785 | H46: =(H45+H44)*15/100 -> 279.13978 | I46: =(I44+I45)*15/100 -> 385.04977
B47: Closing | G47: =G45-G46 -> 860.115 | H47: =H44+H45-H46 -> 1581.7921 | I47: 2181.8374
B49: Total depreciation for the year | D49: =D40 -> 850 | E49: =E40 -> 1002 | F49: =F40 -> 1074 | G49: =G40+G46 -> 1122.7317 | H49: =H40+H46 -> 1156.9214 | I49: =I40+I46 -> 1178.6057
B50: Net Closing Value of Block | D50: =D42 -> 5200 | E50: 5479 | F50: 10119 | G50: =G42+G47 -> 10008.168 | H50: =H42+H47 -> 9852.0638 | I50: =I42+I47 -> 9658.5532
B52: Note 8
...

Sheet Charts
B2: Particulars | C2: 2018-19 | D2: 2019-20 | E2: 2020-21 | F2: 2021-22 | G2: 2022-23 | H2: 2023-24 | J2: Particulars | K2: 2018-19 | L2: 2019-20 | M2: 2020-21 | N2: 2021-22 | O2: 2022-23 | P2: 2023-24 | R2: Particulars | S2: 2019-20 | T2: 2020-21 | U2: 2021-22 | V2: 2022-23 | W2: 2023-24
B3: Sales growth rate | C3: 0.1059 | D3: 0.012 | E3: 0.1821 | F3: 0.10044 | G3: 0.109468 | H3: 0.1119816 | J3: Capital Employed | K3: =SUM('Balance Sheet'!D5:D7) -> 15229 | L3: =SUM('Balance Sheet'!E5:E7) -> 17424 | M3: =SUM('Balance Sheet'!F5:F7) -> 29100 | N3: =SUM('Balance Sheet'!G5:G7) -> 38916.368 | O3: =SUM('Balance Sheet'!H5:H7) -> 52392.57 | P3: =SUM('Balance Sheet'!I5:I7) -> 66481.721 | R3: Operating Cashflow | S3: ='Cash Flow'!C21 -> 10117 | T3: ='Cash Flow'!D21 -> 16902 | U3: ='Cash Flow'!E21 -> 8122.4447 | V3: ='Cash Flow'!F21 -> 15585.509 | W3: ='Cash Flow'!G21 -> 14671.294
B4: Net profit growth rate | D4: =D5-C5 -> 0.02505504 | E4: =E5-D5 -> 0.0068680274 | F4: =F5-E5 -> 0.0029877116 | G4: =G5-F5 -> 0.048402927 | H4: =H5-G5 -> -0.011978891 | J4: EBIT | K4: ='Profit & Loss'!D21+'Profit & Loss'!D20+'Profit & Loss'!D18 -> 8352 | L4: ='Profit & Loss'!E21+'Profit & Loss'!E20+'Profit & Loss'!E18 -> 9368 | M4: ='Profit & Loss'!F21+'Profit & Loss'!F20+'Profit & Loss'!F18 -> 11129 | N4: ='Profit & Loss'!G21+'Profit & Loss'!G20+'Profit & Loss'!G18 -> 13558.993 | O4: ='Profit & Loss'!H21+'Profit & Loss'!H20+'Profit & Loss'!H18 -> 19022.279 | P4: ='Profit & Loss'!I21+'Profit & Loss'!I20+'Profit & Loss'!I18 -> 20056.451 | R4: Financing Cashflow | S4: ='Cash Flow'!C35 -> -238 | T4: ='Cash Flow'!D35 -> -138 | U4: ='Cash Flow'!E35 -> 278.1496 | V4: ='Cash Flow'!F35 -> 105.90019 | W4: ='Cash Flow'!G35 -> -10.178701
B5: Net profit Margin =NP/Sales | C5: ='Profit & Loss'!D21/'Profit & Loss'!D5 -> 0.14637497 | D5: ='Profit & Loss'!E21/'Profit & Loss'!E5 -> 0.17143001 | E5: ='Profit & Loss'!F21/'Profit & Loss'!F5 -> 0.17829804 | F5: ='Profit & Loss'!G21/'Profit & Loss'!G5 -> 0.18128575 | G5: ='Profit & Loss'!H21/'Profit & Loss'!H5 -> 0.22968867 | H5: ='Profit & Loss'!I21/'Profit & Loss'!I5 -> 0.21770978 | J5: Return on Capital Employed | K5: =K4/K3 -> 0.54842734 | L5: =L4/L3 -> 0.53764922 | M5: =M4/M3 -> 0.38243986 | N5: =N4/N3 -> 0.34841363 | O5: =O4/O3 -> 0.36307208 | P5: =P4/P3 -> 0.30168369 | R5: Investing Cashflow | S5: ='Cash Flow'!C29 -> 467 | T5: ='Cash Flow'!D29 -> -6071 | U5: ='Cash Flow'!E29 -> -915.4 | V5: ='Cash Flow'!F29 -> -911.76683 | W5: ='Cash Flow'!G29 -> -904.35138
N6: =M5-N5 -> 0.034026229 | R6: Total | S6: =S3+S4+S5 -> 10346 | T6: =T3+T4+T5 -> 10693 | U6: =U3+U4+U5 -> 7485.1943 | V6: =V3+V4+V5 -> 14779.643 | W6: =W3+W4+W5 -> 13756.764
R8: Particulars | S8: 2019-20 | T8: 2020-21 | U8: 2021-22 | V8: 2022-23 | W8: 2023-24
R9: Operating Cashflow | S9: =S3/S$6 -> 0.97786584 | T9: =T3/T$6 -> 1.5806602 | U9: =U3/U$6 -> 1.0851348 | V9: =V3/V$6 -> 1.0545254 | W9: =W3/W$6 -> 1.0664786
R10: Financing Cashflow | S10: =S4/$S$6 -> -0.02300406 | T10: =T4/T$6 -> -0.012905639 | U10: =U4/U$6 -> 0.03715997 | V10: =V4/V$6 -> 0.0071652744 | W10: =W4/W$6 -> -0.0007399052
R11: Investing Cashflow | S11: =S5/$S$6 -> 0.045138218 | T11: =T5/T$6 -> -0.56775461 | U11: =U5/U$6 -> -0.12229475 | V11: =V5/V$6 -> -0.061690723 | W11: =W5/W$6 -> -0.06573867
R12: Total | S12: =S6/$S$6 -> 1 | T12: =T6/T$6 -> 1 | U12: =U6/U$6 -> 1 | V12: =V6/V$6 -> 1 | W12: =W6/W$6 -> 1
B24: In the year 2019-20, Net earnings growth was 1.31% higher than Sales growth which was a good sign. In years 2020-21 and 2021-22, Sales grew 18.21% and 10.04% but Net profit growth was just 0.69% and 0.30% which is not considered good and it shows the company doesn't have a good cost of control and cannot materialize its high sales into earnings for shareholders. In the year 2022-23,the sale will grow by 10.95% and Net Profit Margin by 4.86%. This is because the company will achieve economies of scale resulting in lower manufacturing cost thereby, increasing the Net Profit Growth Margin by 4.86%. In the year 2023-24, the sale will grow by 11.20% but Net Profit will fall by 1.20%. | J24: The company's Return on Equity was much higher in 2018-19 and 2019-20. High ROCE shows that the company is earning a high return with the given capital employed. It dropped by 16.31% and by 3.40% in 2020-21 and 2021-22 due to the increase in Reserves and Surplus resulting in increase in Capital employment. It will increase by 1.45% in the year 2022-23 which is a good sign but again it will drop by 6.15% in a year due to increase in capital employed and lower return i.r.o. capital employed.
R32: The higher the company have operating cashflow, it is considered good for company's profitability, liquidity and becoming self-reliant i.e. reduce debt. Company always tries to maintain good amount of operating cashflows which is good sign for it's investors. Company will invest 10% of Assets in capital expenditure for upgradation and for fresh Assets regularly for upcoming 3 years and it receives interest on investment. thus, company seems to invest normally in the range of 6 to 12% of cashflows in investing activites. In the year 2020-21, It invested 57% of total cash inflow in Fixed Assets and Investments. Company will borrow 60% of CAPEX in each upcoming 3 years and will also start it's repayment of principal and interest amoun. thus, cashflow from financing activities set offs by receipts and payments of cash. It shows net effect in cash flow statement ranging from 0 to 5% of proportion in financing activities.
